2024-02-02 15:38 ERROR Traceback (most recent call last):
  File "C:\Users\user\Desktop\program\Reinforcement_learninng\lib\site-packages\sqlalchemy\engine\base.py", line 1969, in _exec_single_context
    self.dialect.do_execute(
  File "C:\Users\user\Desktop\program\Reinforcement_learninng\lib\site-packages\sqlalchemy\engine\default.py", line 922, in do_execute
    cursor.execute(statement, parameters)
  File "C:\Users\user\Desktop\program\Reinforcement_learninng\lib\site-packages\pymysql\cursors.py", line 153, in execute
    result = self._query(query)
  File "C:\Users\user\Desktop\program\Reinforcement_learninng\lib\site-packages\pymysql\cursors.py", line 322, in _query
    conn.query(q)
  File "C:\Users\user\Desktop\program\Reinforcement_learninng\lib\site-packages\pymysql\connections.py", line 558, in query
    self._affected_rows = self._read_query_result(unbuffered=unbuffered)
  File "C:\Users\user\Desktop\program\Reinforcement_learninng\lib\site-packages\pymysql\connections.py", line 822, in _read_query_result
    result.read()
  File "C:\Users\user\Desktop\program\Reinforcement_learninng\lib\site-packages\pymysql\connections.py", line 1200, in read
    first_packet = self.connection._read_packet()
  File "C:\Users\user\Desktop\program\Reinforcement_learninng\lib\site-packages\pymysql\connections.py", line 772, in _read_packet
    packet.raise_for_error()
  File "C:\Users\user\Desktop\program\Reinforcement_learninng\lib\site-packages\pymysql\protocol.py", line 221, in raise_for_error
    err.raise_mysql_exception(self._data)
  File "C:\Users\user\Desktop\program\Reinforcement_learninng\lib\site-packages\pymysql\err.py", line 143, in raise_mysql_exception
    raise errorclass(errno, errval)
pymysql.err.OperationalError: (1050, "Table 'orderresult' already exists")

The above exception was the direct cause of the following exception:

Traceback (most recent call last):
  File "c:\Users\user\Desktop\program\Reinforcement_learninng\finrl_achieve\project\Database\SQL_operate.py", line 35, in change_db_data
    conn.execute(text(text_msg))
  File "C:\Users\user\Desktop\program\Reinforcement_learninng\lib\site-packages\sqlalchemy\engine\base.py", line 1416, in execute
    return meth(
  File "C:\Users\user\Desktop\program\Reinforcement_learninng\lib\site-packages\sqlalchemy\sql\elements.py", line 516, in _execute_on_connection
    return connection._execute_clauseelement(
  File "C:\Users\user\Desktop\program\Reinforcement_learninng\lib\site-packages\sqlalchemy\engine\base.py", line 1639, in _execute_clauseelement
    ret = self._execute_context(
  File "C:\Users\user\Desktop\program\Reinforcement_learninng\lib\site-packages\sqlalchemy\engine\base.py", line 1848, in _execute_context
    return self._exec_single_context(
  File "C:\Users\user\Desktop\program\Reinforcement_learninng\lib\site-packages\sqlalchemy\engine\base.py", line 1988, in _exec_single_context
    self._handle_dbapi_exception(
  File "C:\Users\user\Desktop\program\Reinforcement_learninng\lib\site-packages\sqlalchemy\engine\base.py", line 2343, in _handle_dbapi_exception
    raise sqlalchemy_exception.with_traceback(exc_info[2]) from e
  File "C:\Users\user\Desktop\program\Reinforcement_learninng\lib\site-packages\sqlalchemy\engine\base.py", line 1969, in _exec_single_context
    self.dialect.do_execute(
  File "C:\Users\user\Desktop\program\Reinforcement_learninng\lib\site-packages\sqlalchemy\engine\default.py", line 922, in do_execute
    cursor.execute(statement, parameters)
  File "C:\Users\user\Desktop\program\Reinforcement_learninng\lib\site-packages\pymysql\cursors.py", line 153, in execute
    result = self._query(query)
  File "C:\Users\user\Desktop\program\Reinforcement_learninng\lib\site-packages\pymysql\cursors.py", line 322, in _query
    conn.query(q)
  File "C:\Users\user\Desktop\program\Reinforcement_learninng\lib\site-packages\pymysql\connections.py", line 558, in query
    self._affected_rows = self._read_query_result(unbuffered=unbuffered)
  File "C:\Users\user\Desktop\program\Reinforcement_learninng\lib\site-packages\pymysql\connections.py", line 822, in _read_query_result
    result.read()
  File "C:\Users\user\Desktop\program\Reinforcement_learninng\lib\site-packages\pymysql\connections.py", line 1200, in read
    first_packet = self.connection._read_packet()
  File "C:\Users\user\Desktop\program\Reinforcement_learninng\lib\site-packages\pymysql\connections.py", line 772, in _read_packet
    packet.raise_for_error()
  File "C:\Users\user\Desktop\program\Reinforcement_learninng\lib\site-packages\pymysql\protocol.py", line 221, in raise_for_error
    err.raise_mysql_exception(self._data)
  File "C:\Users\user\Desktop\program\Reinforcement_learninng\lib\site-packages\pymysql\err.py", line 143, in raise_mysql_exception
    raise errorclass(errno, errval)
sqlalchemy.exc.OperationalError: (pymysql.err.OperationalError) (1050, "Table 'orderresult' already exists")
[SQL: 
                CREATE TABLE `crypto_data`.`orderresult`(
                    `orderId` BIGINT NOT NULL,
                    `order_info` TEXT NOT NULL,
                    PRIMARY KEY(`orderId`)
                );
            ]
(Background on this error at: https://sqlalche.me/e/20/e3q8)

2024-02-02 15:41 ERROR Traceback (most recent call last):
  File "C:\Users\user\Desktop\program\Reinforcement_learninng\lib\site-packages\sqlalchemy\engine\base.py", line 1969, in _exec_single_context
    self.dialect.do_execute(
  File "C:\Users\user\Desktop\program\Reinforcement_learninng\lib\site-packages\sqlalchemy\engine\default.py", line 922, in do_execute
    cursor.execute(statement, parameters)
  File "C:\Users\user\Desktop\program\Reinforcement_learninng\lib\site-packages\pymysql\cursors.py", line 153, in execute
    result = self._query(query)
  File "C:\Users\user\Desktop\program\Reinforcement_learninng\lib\site-packages\pymysql\cursors.py", line 322, in _query
    conn.query(q)
  File "C:\Users\user\Desktop\program\Reinforcement_learninng\lib\site-packages\pymysql\connections.py", line 558, in query
    self._affected_rows = self._read_query_result(unbuffered=unbuffered)
  File "C:\Users\user\Desktop\program\Reinforcement_learninng\lib\site-packages\pymysql\connections.py", line 822, in _read_query_result
    result.read()
  File "C:\Users\user\Desktop\program\Reinforcement_learninng\lib\site-packages\pymysql\connections.py", line 1200, in read
    first_packet = self.connection._read_packet()
  File "C:\Users\user\Desktop\program\Reinforcement_learninng\lib\site-packages\pymysql\connections.py", line 772, in _read_packet
    packet.raise_for_error()
  File "C:\Users\user\Desktop\program\Reinforcement_learninng\lib\site-packages\pymysql\protocol.py", line 221, in raise_for_error
    err.raise_mysql_exception(self._data)
  File "C:\Users\user\Desktop\program\Reinforcement_learninng\lib\site-packages\pymysql\err.py", line 143, in raise_mysql_exception
    raise errorclass(errno, errval)
pymysql.err.ProgrammingError: (1064, "You have an error in your SQL syntax; check the manual that corresponds to your MySQL server version for the right syntax to use near 'ID` varchar(255) NOT NULL,\n                    `systeam_datetime` varchar(255) N' at line 2")

The above exception was the direct cause of the following exception:

Traceback (most recent call last):
  File "c:\Users\user\Desktop\program\Reinforcement_learninng\finrl_achieve\project\Database\SQL_operate.py", line 35, in change_db_data
    conn.execute(text(text_msg))
  File "C:\Users\user\Desktop\program\Reinforcement_learninng\lib\site-packages\sqlalchemy\engine\base.py", line 1416, in execute
    return meth(
  File "C:\Users\user\Desktop\program\Reinforcement_learninng\lib\site-packages\sqlalchemy\sql\elements.py", line 516, in _execute_on_connection
    return connection._execute_clauseelement(
  File "C:\Users\user\Desktop\program\Reinforcement_learninng\lib\site-packages\sqlalchemy\engine\base.py", line 1639, in _execute_clauseelement
    ret = self._execute_context(
  File "C:\Users\user\Desktop\program\Reinforcement_learninng\lib\site-packages\sqlalchemy\engine\base.py", line 1848, in _execute_context
    return self._exec_single_context(
  File "C:\Users\user\Desktop\program\Reinforcement_learninng\lib\site-packages\sqlalchemy\engine\base.py", line 1988, in _exec_single_context
    self._handle_dbapi_exception(
  File "C:\Users\user\Desktop\program\Reinforcement_learninng\lib\site-packages\sqlalchemy\engine\base.py", line 2343, in _handle_dbapi_exception
    raise sqlalchemy_exception.with_traceback(exc_info[2]) from e
  File "C:\Users\user\Desktop\program\Reinforcement_learninng\lib\site-packages\sqlalchemy\engine\base.py", line 1969, in _exec_single_context
    self.dialect.do_execute(
  File "C:\Users\user\Desktop\program\Reinforcement_learninng\lib\site-packages\sqlalchemy\engine\default.py", line 922, in do_execute
    cursor.execute(statement, parameters)
  File "C:\Users\user\Desktop\program\Reinforcement_learninng\lib\site-packages\pymysql\cursors.py", line 153, in execute
    result = self._query(query)
  File "C:\Users\user\Desktop\program\Reinforcement_learninng\lib\site-packages\pymysql\cursors.py", line 322, in _query
    conn.query(q)
  File "C:\Users\user\Desktop\program\Reinforcement_learninng\lib\site-packages\pymysql\connections.py", line 558, in query
    self._affected_rows = self._read_query_result(unbuffered=unbuffered)
  File "C:\Users\user\Desktop\program\Reinforcement_learninng\lib\site-packages\pymysql\connections.py", line 822, in _read_query_result
    result.read()
  File "C:\Users\user\Desktop\program\Reinforcement_learninng\lib\site-packages\pymysql\connections.py", line 1200, in read
    first_packet = self.connection._read_packet()
  File "C:\Users\user\Desktop\program\Reinforcement_learninng\lib\site-packages\pymysql\connections.py", line 772, in _read_packet
    packet.raise_for_error()
  File "C:\Users\user\Desktop\program\Reinforcement_learninng\lib\site-packages\pymysql\protocol.py", line 221, in raise_for_error
    err.raise_mysql_exception(self._data)
  File "C:\Users\user\Desktop\program\Reinforcement_learninng\lib\site-packages\pymysql\err.py", line 143, in raise_mysql_exception
    raise errorclass(errno, errval)
sqlalchemy.exc.ProgrammingError: (pymysql.err.ProgrammingError) (1064, "You have an error in your SQL syntax; check the manual that corresponds to your MySQL server version for the right syntax to use near 'ID` varchar(255) NOT NULL,\n                    `systeam_datetime` varchar(255) N' at line 2")
[SQL: 
                CREATE TABLE `crypto_data`.`interval_record(
                    `ID` varchar(255) NOT NULL,
                    `systeam_datetime` varchar(255) NOT NULL,
                    PRIMARY KEY(`ID`));
            ]
(Background on this error at: https://sqlalche.me/e/20/f405)

2024-02-02 16:05 ERROR Traceback (most recent call last):
  File "c:\Users\user\Desktop\program\Reinforcement_learninng\finrl_achieve\project\Database\SQL_operate.py", line 46, in read_Dateframe
    self.userconn = router.Router().mysql_conn
  File "c:\Users\user\Desktop\program\Reinforcement_learninng\finrl_achieve\project\Database\router.py", line 13, in __init__
    self._mysql_conn = self.get_mysql_conn()
  File "c:\Users\user\Desktop\program\Reinforcement_learninng\finrl_achieve\project\Database\router.py", line 28, in get_mysql_conn
    connect = engine.connect()
  File "C:\Users\user\Desktop\program\Reinforcement_learninng\lib\site-packages\sqlalchemy\engine\base.py", line 3268, in connect
    return self._connection_cls(self)
  File "C:\Users\user\Desktop\program\Reinforcement_learninng\lib\site-packages\sqlalchemy\engine\base.py", line 145, in __init__
    self._dbapi_connection = engine.raw_connection()
  File "C:\Users\user\Desktop\program\Reinforcement_learninng\lib\site-packages\sqlalchemy\engine\base.py", line 3292, in raw_connection
    return self.pool.connect()
  File "C:\Users\user\Desktop\program\Reinforcement_learninng\lib\site-packages\sqlalchemy\pool\base.py", line 452, in connect
    return _ConnectionFairy._checkout(self)
  File "C:\Users\user\Desktop\program\Reinforcement_learninng\lib\site-packages\sqlalchemy\pool\base.py", line 1269, in _checkout
    fairy = _ConnectionRecord.checkout(pool)
  File "C:\Users\user\Desktop\program\Reinforcement_learninng\lib\site-packages\sqlalchemy\pool\base.py", line 716, in checkout
    rec = pool._do_get()
  File "C:\Users\user\Desktop\program\Reinforcement_learninng\lib\site-packages\sqlalchemy\pool\impl.py", line 169, in _do_get
    with util.safe_reraise():
  File "C:\Users\user\Desktop\program\Reinforcement_learninng\lib\site-packages\sqlalchemy\util\langhelpers.py", line 146, in __exit__
    raise exc_value.with_traceback(exc_tb)
  File "C:\Users\user\Desktop\program\Reinforcement_learninng\lib\site-packages\sqlalchemy\pool\impl.py", line 167, in _do_get
    return self._create_connection()
  File "C:\Users\user\Desktop\program\Reinforcement_learninng\lib\site-packages\sqlalchemy\pool\base.py", line 393, in _create_connection
    return _ConnectionRecord(self)
  File "C:\Users\user\Desktop\program\Reinforcement_learninng\lib\site-packages\sqlalchemy\pool\base.py", line 678, in __init__
    self.__connect()
  File "C:\Users\user\Desktop\program\Reinforcement_learninng\lib\site-packages\sqlalchemy\pool\base.py", line 902, in __connect
    with util.safe_reraise():
  File "C:\Users\user\Desktop\program\Reinforcement_learninng\lib\site-packages\sqlalchemy\util\langhelpers.py", line 146, in __exit__
    raise exc_value.with_traceback(exc_tb)
  File "C:\Users\user\Desktop\program\Reinforcement_learninng\lib\site-packages\sqlalchemy\pool\base.py", line 898, in __connect
    self.dbapi_connection = connection = pool._invoke_creator(self)
  File "C:\Users\user\Desktop\program\Reinforcement_learninng\lib\site-packages\sqlalchemy\engine\create.py", line 637, in connect
    return dialect.connect(*cargs, **cparams)
  File "C:\Users\user\Desktop\program\Reinforcement_learninng\lib\site-packages\sqlalchemy\engine\default.py", line 616, in connect
    return self.loaded_dbapi.connect(*cargs, **cparams)
  File "C:\Users\user\Desktop\program\Reinforcement_learninng\lib\site-packages\pymysql\connections.py", line 358, in __init__
    self.connect()
  File "C:\Users\user\Desktop\program\Reinforcement_learninng\lib\site-packages\pymysql\connections.py", line 644, in connect
    sock = socket.create_connection(
  File "C:\Program Files\Python310\lib\socket.py", line 833, in create_connection
    sock.connect(sa)
KeyboardInterrupt

2024-02-02 16:05 ERROR Traceback (most recent call last):
  File "c:\Users\user\Desktop\program\Reinforcement_learninng\finrl_achieve\project\Database\SQL_operate.py", line 48, in read_Dateframe
    return pd.read_sql(text_msg, con=conn)
  File "C:\Users\user\Desktop\program\Reinforcement_learninng\lib\site-packages\pandas\io\sql.py", line 724, in read_sql
    return pandas_sql.read_table(
  File "C:\Users\user\Desktop\program\Reinforcement_learninng\lib\site-packages\pandas\io\sql.py", line 1728, in read_table
    self.meta.reflect(bind=self.con, only=[table_name], views=True)
  File "C:\Users\user\Desktop\program\Reinforcement_learninng\lib\site-packages\sqlalchemy\sql\schema.py", line 5741, in reflect
    insp.get_table_names(schema)
  File "C:\Users\user\Desktop\program\Reinforcement_learninng\lib\site-packages\sqlalchemy\engine\reflection.py", line 396, in get_table_names
    return self.dialect.get_table_names(
  File "<string>", line 2, in get_table_names
  File "C:\Users\user\Desktop\program\Reinforcement_learninng\lib\site-packages\sqlalchemy\engine\reflection.py", line 97, in cache
    ret = fn(self, con, *args, **kw)
  File "C:\Users\user\Desktop\program\Reinforcement_learninng\lib\site-packages\sqlalchemy\dialects\mysql\base.py", line 2885, in get_table_names
    rp = connection.exec_driver_sql(
  File "C:\Users\user\Desktop\program\Reinforcement_learninng\lib\site-packages\sqlalchemy\engine\base.py", line 1778, in exec_driver_sql
    ret = self._execute_context(
  File "C:\Users\user\Desktop\program\Reinforcement_learninng\lib\site-packages\sqlalchemy\engine\base.py", line 1848, in _execute_context
    return self._exec_single_context(
  File "C:\Users\user\Desktop\program\Reinforcement_learninng\lib\site-packages\sqlalchemy\engine\base.py", line 1988, in _exec_single_context
    self._handle_dbapi_exception(
  File "C:\Users\user\Desktop\program\Reinforcement_learninng\lib\site-packages\sqlalchemy\engine\base.py", line 2346, in _handle_dbapi_exception
    raise exc_info[1].with_traceback(exc_info[2])
  File "C:\Users\user\Desktop\program\Reinforcement_learninng\lib\site-packages\sqlalchemy\engine\base.py", line 1969, in _exec_single_context
    self.dialect.do_execute(
  File "C:\Users\user\Desktop\program\Reinforcement_learninng\lib\site-packages\sqlalchemy\engine\default.py", line 922, in do_execute
    cursor.execute(statement, parameters)
  File "C:\Users\user\Desktop\program\Reinforcement_learninng\lib\site-packages\pymysql\cursors.py", line 153, in execute
    result = self._query(query)
  File "C:\Users\user\Desktop\program\Reinforcement_learninng\lib\site-packages\pymysql\cursors.py", line 322, in _query
    conn.query(q)
  File "C:\Users\user\Desktop\program\Reinforcement_learninng\lib\site-packages\pymysql\connections.py", line 558, in query
    self._affected_rows = self._read_query_result(unbuffered=unbuffered)
  File "C:\Users\user\Desktop\program\Reinforcement_learninng\lib\site-packages\pymysql\connections.py", line 822, in _read_query_result
    result.read()
  File "C:\Users\user\Desktop\program\Reinforcement_learninng\lib\site-packages\pymysql\connections.py", line 1200, in read
    first_packet = self.connection._read_packet()
  File "C:\Users\user\Desktop\program\Reinforcement_learninng\lib\site-packages\pymysql\connections.py", line 739, in _read_packet
    packet_header = self._read_bytes(4)
  File "C:\Users\user\Desktop\program\Reinforcement_learninng\lib\site-packages\pymysql\connections.py", line 779, in _read_bytes
    data = self._rfile.read(num_bytes)
  File "C:\Program Files\Python310\lib\socket.py", line 705, in readinto
    return self._sock.recv_into(b)
KeyboardInterrupt

2024-02-02 16:05 ERROR Traceback (most recent call last):
  File "c:\Users\user\Desktop\program\Reinforcement_learninng\finrl_achieve\project\Database\SQL_operate.py", line 48, in read_Dateframe
    return pd.read_sql(text_msg, con=conn)
  File "C:\Users\user\Desktop\program\Reinforcement_learninng\lib\site-packages\pandas\io\sql.py", line 724, in read_sql
    return pandas_sql.read_table(
  File "C:\Users\user\Desktop\program\Reinforcement_learninng\lib\site-packages\pandas\io\sql.py", line 1728, in read_table
    self.meta.reflect(bind=self.con, only=[table_name], views=True)
  File "C:\Users\user\Desktop\program\Reinforcement_learninng\lib\site-packages\sqlalchemy\sql\schema.py", line 5745, in reflect
    available.update(insp.get_view_names(schema))
  File "C:\Users\user\Desktop\program\Reinforcement_learninng\lib\site-packages\sqlalchemy\engine\reflection.py", line 766, in get_view_names
    return self.dialect.get_view_names(
  File "<string>", line 2, in get_view_names
  File "C:\Users\user\Desktop\program\Reinforcement_learninng\lib\site-packages\sqlalchemy\engine\reflection.py", line 97, in cache
    ret = fn(self, con, *args, **kw)
  File "C:\Users\user\Desktop\program\Reinforcement_learninng\lib\site-packages\sqlalchemy\dialects\mysql\base.py", line 2901, in get_view_names
    rp = connection.exec_driver_sql(
  File "C:\Users\user\Desktop\program\Reinforcement_learninng\lib\site-packages\sqlalchemy\engine\base.py", line 1778, in exec_driver_sql
    ret = self._execute_context(
  File "C:\Users\user\Desktop\program\Reinforcement_learninng\lib\site-packages\sqlalchemy\engine\base.py", line 1848, in _execute_context
    return self._exec_single_context(
  File "C:\Users\user\Desktop\program\Reinforcement_learninng\lib\site-packages\sqlalchemy\engine\base.py", line 1988, in _exec_single_context
    self._handle_dbapi_exception(
  File "C:\Users\user\Desktop\program\Reinforcement_learninng\lib\site-packages\sqlalchemy\engine\base.py", line 2346, in _handle_dbapi_exception
    raise exc_info[1].with_traceback(exc_info[2])
  File "C:\Users\user\Desktop\program\Reinforcement_learninng\lib\site-packages\sqlalchemy\engine\base.py", line 1969, in _exec_single_context
    self.dialect.do_execute(
  File "C:\Users\user\Desktop\program\Reinforcement_learninng\lib\site-packages\sqlalchemy\engine\default.py", line 922, in do_execute
    cursor.execute(statement, parameters)
  File "C:\Users\user\Desktop\program\Reinforcement_learninng\lib\site-packages\pymysql\cursors.py", line 153, in execute
    result = self._query(query)
  File "C:\Users\user\Desktop\program\Reinforcement_learninng\lib\site-packages\pymysql\cursors.py", line 322, in _query
    conn.query(q)
  File "C:\Users\user\Desktop\program\Reinforcement_learninng\lib\site-packages\pymysql\connections.py", line 558, in query
    self._affected_rows = self._read_query_result(unbuffered=unbuffered)
  File "C:\Users\user\Desktop\program\Reinforcement_learninng\lib\site-packages\pymysql\connections.py", line 822, in _read_query_result
    result.read()
  File "C:\Users\user\Desktop\program\Reinforcement_learninng\lib\site-packages\pymysql\connections.py", line 1200, in read
    first_packet = self.connection._read_packet()
  File "C:\Users\user\Desktop\program\Reinforcement_learninng\lib\site-packages\pymysql\connections.py", line 739, in _read_packet
    packet_header = self._read_bytes(4)
  File "C:\Users\user\Desktop\program\Reinforcement_learninng\lib\site-packages\pymysql\connections.py", line 779, in _read_bytes
    data = self._rfile.read(num_bytes)
  File "C:\Program Files\Python310\lib\socket.py", line 705, in readinto
    return self._sock.recv_into(b)
KeyboardInterrupt

2024-02-02 16:05 ERROR Traceback (most recent call last):
  File "c:\Users\user\Desktop\program\Reinforcement_learninng\finrl_achieve\project\Database\SQL_operate.py", line 48, in read_Dateframe
    return pd.read_sql(text_msg, con=conn)
  File "C:\Users\user\Desktop\program\Reinforcement_learninng\lib\site-packages\pandas\io\sql.py", line 724, in read_sql
    return pandas_sql.read_table(
  File "C:\Users\user\Desktop\program\Reinforcement_learninng\lib\site-packages\pandas\io\sql.py", line 1728, in read_table
    self.meta.reflect(bind=self.con, only=[table_name], views=True)
  File "C:\Users\user\Desktop\program\Reinforcement_learninng\lib\site-packages\sqlalchemy\sql\schema.py", line 5741, in reflect
    insp.get_table_names(schema)
  File "C:\Users\user\Desktop\program\Reinforcement_learninng\lib\site-packages\sqlalchemy\engine\reflection.py", line 396, in get_table_names
    return self.dialect.get_table_names(
  File "<string>", line 2, in get_table_names
  File "C:\Users\user\Desktop\program\Reinforcement_learninng\lib\site-packages\sqlalchemy\engine\reflection.py", line 97, in cache
    ret = fn(self, con, *args, **kw)
  File "C:\Users\user\Desktop\program\Reinforcement_learninng\lib\site-packages\sqlalchemy\dialects\mysql\base.py", line 2885, in get_table_names
    rp = connection.exec_driver_sql(
  File "C:\Users\user\Desktop\program\Reinforcement_learninng\lib\site-packages\sqlalchemy\engine\base.py", line 1778, in exec_driver_sql
    ret = self._execute_context(
  File "C:\Users\user\Desktop\program\Reinforcement_learninng\lib\site-packages\sqlalchemy\engine\base.py", line 1848, in _execute_context
    return self._exec_single_context(
  File "C:\Users\user\Desktop\program\Reinforcement_learninng\lib\site-packages\sqlalchemy\engine\base.py", line 1988, in _exec_single_context
    self._handle_dbapi_exception(
  File "C:\Users\user\Desktop\program\Reinforcement_learninng\lib\site-packages\sqlalchemy\engine\base.py", line 2346, in _handle_dbapi_exception
    raise exc_info[1].with_traceback(exc_info[2])
  File "C:\Users\user\Desktop\program\Reinforcement_learninng\lib\site-packages\sqlalchemy\engine\base.py", line 1969, in _exec_single_context
    self.dialect.do_execute(
  File "C:\Users\user\Desktop\program\Reinforcement_learninng\lib\site-packages\sqlalchemy\engine\default.py", line 922, in do_execute
    cursor.execute(statement, parameters)
  File "C:\Users\user\Desktop\program\Reinforcement_learninng\lib\site-packages\pymysql\cursors.py", line 153, in execute
    result = self._query(query)
  File "C:\Users\user\Desktop\program\Reinforcement_learninng\lib\site-packages\pymysql\cursors.py", line 322, in _query
    conn.query(q)
  File "C:\Users\user\Desktop\program\Reinforcement_learninng\lib\site-packages\pymysql\connections.py", line 558, in query
    self._affected_rows = self._read_query_result(unbuffered=unbuffered)
  File "C:\Users\user\Desktop\program\Reinforcement_learninng\lib\site-packages\pymysql\connections.py", line 822, in _read_query_result
    result.read()
  File "C:\Users\user\Desktop\program\Reinforcement_learninng\lib\site-packages\pymysql\connections.py", line 1200, in read
    first_packet = self.connection._read_packet()
  File "C:\Users\user\Desktop\program\Reinforcement_learninng\lib\site-packages\pymysql\connections.py", line 739, in _read_packet
    packet_header = self._read_bytes(4)
  File "C:\Users\user\Desktop\program\Reinforcement_learninng\lib\site-packages\pymysql\connections.py", line 779, in _read_bytes
    data = self._rfile.read(num_bytes)
  File "C:\Program Files\Python310\lib\socket.py", line 705, in readinto
    return self._sock.recv_into(b)
KeyboardInterrupt

2024-02-02 16:08 ERROR Traceback (most recent call last):
  File "C:\Users\user\Desktop\program\Reinforcement_learninng\lib\site-packages\sqlalchemy\engine\base.py", line 1969, in _exec_single_context
    self.dialect.do_execute(
  File "C:\Users\user\Desktop\program\Reinforcement_learninng\lib\site-packages\sqlalchemy\engine\default.py", line 922, in do_execute
    cursor.execute(statement, parameters)
  File "C:\Users\user\Desktop\program\Reinforcement_learninng\lib\site-packages\pymysql\cursors.py", line 153, in execute
    result = self._query(query)
  File "C:\Users\user\Desktop\program\Reinforcement_learninng\lib\site-packages\pymysql\cursors.py", line 322, in _query
    conn.query(q)
  File "C:\Users\user\Desktop\program\Reinforcement_learninng\lib\site-packages\pymysql\connections.py", line 558, in query
    self._affected_rows = self._read_query_result(unbuffered=unbuffered)
  File "C:\Users\user\Desktop\program\Reinforcement_learninng\lib\site-packages\pymysql\connections.py", line 822, in _read_query_result
    result.read()
  File "C:\Users\user\Desktop\program\Reinforcement_learninng\lib\site-packages\pymysql\connections.py", line 1200, in read
    first_packet = self.connection._read_packet()
  File "C:\Users\user\Desktop\program\Reinforcement_learninng\lib\site-packages\pymysql\connections.py", line 772, in _read_packet
    packet.raise_for_error()
  File "C:\Users\user\Desktop\program\Reinforcement_learninng\lib\site-packages\pymysql\protocol.py", line 221, in raise_for_error
    err.raise_mysql_exception(self._data)
  File "C:\Users\user\Desktop\program\Reinforcement_learninng\lib\site-packages\pymysql\err.py", line 143, in raise_mysql_exception
    raise errorclass(errno, errval)
pymysql.err.IntegrityError: (1062, "Duplicate entry '1' for key 'interval_record.PRIMARY'")

The above exception was the direct cause of the following exception:

Traceback (most recent call last):
  File "c:\Users\user\Desktop\program\Reinforcement_learninng\finrl_achieve\project\Database\SQL_operate.py", line 35, in change_db_data
    conn.execute(text(text_msg))
  File "C:\Users\user\Desktop\program\Reinforcement_learninng\lib\site-packages\sqlalchemy\engine\base.py", line 1416, in execute
    return meth(
  File "C:\Users\user\Desktop\program\Reinforcement_learninng\lib\site-packages\sqlalchemy\sql\elements.py", line 516, in _execute_on_connection
    return connection._execute_clauseelement(
  File "C:\Users\user\Desktop\program\Reinforcement_learninng\lib\site-packages\sqlalchemy\engine\base.py", line 1639, in _execute_clauseelement
    ret = self._execute_context(
  File "C:\Users\user\Desktop\program\Reinforcement_learninng\lib\site-packages\sqlalchemy\engine\base.py", line 1848, in _execute_context
    return self._exec_single_context(
  File "C:\Users\user\Desktop\program\Reinforcement_learninng\lib\site-packages\sqlalchemy\engine\base.py", line 1988, in _exec_single_context
    self._handle_dbapi_exception(
  File "C:\Users\user\Desktop\program\Reinforcement_learninng\lib\site-packages\sqlalchemy\engine\base.py", line 2343, in _handle_dbapi_exception
    raise sqlalchemy_exception.with_traceback(exc_info[2]) from e
  File "C:\Users\user\Desktop\program\Reinforcement_learninng\lib\site-packages\sqlalchemy\engine\base.py", line 1969, in _exec_single_context
    self.dialect.do_execute(
  File "C:\Users\user\Desktop\program\Reinforcement_learninng\lib\site-packages\sqlalchemy\engine\default.py", line 922, in do_execute
    cursor.execute(statement, parameters)
  File "C:\Users\user\Desktop\program\Reinforcement_learninng\lib\site-packages\pymysql\cursors.py", line 153, in execute
    result = self._query(query)
  File "C:\Users\user\Desktop\program\Reinforcement_learninng\lib\site-packages\pymysql\cursors.py", line 322, in _query
    conn.query(q)
  File "C:\Users\user\Desktop\program\Reinforcement_learninng\lib\site-packages\pymysql\connections.py", line 558, in query
    self._affected_rows = self._read_query_result(unbuffered=unbuffered)
  File "C:\Users\user\Desktop\program\Reinforcement_learninng\lib\site-packages\pymysql\connections.py", line 822, in _read_query_result
    result.read()
  File "C:\Users\user\Desktop\program\Reinforcement_learninng\lib\site-packages\pymysql\connections.py", line 1200, in read
    first_packet = self.connection._read_packet()
  File "C:\Users\user\Desktop\program\Reinforcement_learninng\lib\site-packages\pymysql\connections.py", line 772, in _read_packet
    packet.raise_for_error()
  File "C:\Users\user\Desktop\program\Reinforcement_learninng\lib\site-packages\pymysql\protocol.py", line 221, in raise_for_error
    err.raise_mysql_exception(self._data)
  File "C:\Users\user\Desktop\program\Reinforcement_learninng\lib\site-packages\pymysql\err.py", line 143, in raise_mysql_exception
    raise errorclass(errno, errval)
sqlalchemy.exc.IntegrityError: (pymysql.err.IntegrityError) (1062, "Duplicate entry '1' for key 'interval_record.PRIMARY'")
[SQL: INSERT INTO `interval_record` VALUES ('1','2024-02-02 16:08:10.435874');]
(Background on this error at: https://sqlalche.me/e/20/gkpj)

2024-02-02 16:08 ERROR Traceback (most recent call last):
  File "C:\Users\user\Desktop\program\Reinforcement_learninng\lib\site-packages\sqlalchemy\engine\base.py", line 1969, in _exec_single_context
    self.dialect.do_execute(
  File "C:\Users\user\Desktop\program\Reinforcement_learninng\lib\site-packages\sqlalchemy\engine\default.py", line 922, in do_execute
    cursor.execute(statement, parameters)
  File "C:\Users\user\Desktop\program\Reinforcement_learninng\lib\site-packages\pymysql\cursors.py", line 153, in execute
    result = self._query(query)
  File "C:\Users\user\Desktop\program\Reinforcement_learninng\lib\site-packages\pymysql\cursors.py", line 322, in _query
    conn.query(q)
  File "C:\Users\user\Desktop\program\Reinforcement_learninng\lib\site-packages\pymysql\connections.py", line 558, in query
    self._affected_rows = self._read_query_result(unbuffered=unbuffered)
  File "C:\Users\user\Desktop\program\Reinforcement_learninng\lib\site-packages\pymysql\connections.py", line 822, in _read_query_result
    result.read()
  File "C:\Users\user\Desktop\program\Reinforcement_learninng\lib\site-packages\pymysql\connections.py", line 1200, in read
    first_packet = self.connection._read_packet()
  File "C:\Users\user\Desktop\program\Reinforcement_learninng\lib\site-packages\pymysql\connections.py", line 772, in _read_packet
    packet.raise_for_error()
  File "C:\Users\user\Desktop\program\Reinforcement_learninng\lib\site-packages\pymysql\protocol.py", line 221, in raise_for_error
    err.raise_mysql_exception(self._data)
  File "C:\Users\user\Desktop\program\Reinforcement_learninng\lib\site-packages\pymysql\err.py", line 143, in raise_mysql_exception
    raise errorclass(errno, errval)
pymysql.err.ProgrammingError: (1064, "You have an error in your SQL syntax; check the manual that corresponds to your MySQL server version for the right syntax to use near 'VALUES ('1','2024-02-02 16:08:28.761521')' at line 1")

The above exception was the direct cause of the following exception:

Traceback (most recent call last):
  File "c:\Users\user\Desktop\program\Reinforcement_learninng\finrl_achieve\project\Database\SQL_operate.py", line 35, in change_db_data
    conn.execute(text(text_msg))
  File "C:\Users\user\Desktop\program\Reinforcement_learninng\lib\site-packages\sqlalchemy\engine\base.py", line 1416, in execute
    return meth(
  File "C:\Users\user\Desktop\program\Reinforcement_learninng\lib\site-packages\sqlalchemy\sql\elements.py", line 516, in _execute_on_connection
    return connection._execute_clauseelement(
  File "C:\Users\user\Desktop\program\Reinforcement_learninng\lib\site-packages\sqlalchemy\engine\base.py", line 1639, in _execute_clauseelement
    ret = self._execute_context(
  File "C:\Users\user\Desktop\program\Reinforcement_learninng\lib\site-packages\sqlalchemy\engine\base.py", line 1848, in _execute_context
    return self._exec_single_context(
  File "C:\Users\user\Desktop\program\Reinforcement_learninng\lib\site-packages\sqlalchemy\engine\base.py", line 1988, in _exec_single_context
    self._handle_dbapi_exception(
  File "C:\Users\user\Desktop\program\Reinforcement_learninng\lib\site-packages\sqlalchemy\engine\base.py", line 2343, in _handle_dbapi_exception
    raise sqlalchemy_exception.with_traceback(exc_info[2]) from e
  File "C:\Users\user\Desktop\program\Reinforcement_learninng\lib\site-packages\sqlalchemy\engine\base.py", line 1969, in _exec_single_context
    self.dialect.do_execute(
  File "C:\Users\user\Desktop\program\Reinforcement_learninng\lib\site-packages\sqlalchemy\engine\default.py", line 922, in do_execute
    cursor.execute(statement, parameters)
  File "C:\Users\user\Desktop\program\Reinforcement_learninng\lib\site-packages\pymysql\cursors.py", line 153, in execute
    result = self._query(query)
  File "C:\Users\user\Desktop\program\Reinforcement_learninng\lib\site-packages\pymysql\cursors.py", line 322, in _query
    conn.query(q)
  File "C:\Users\user\Desktop\program\Reinforcement_learninng\lib\site-packages\pymysql\connections.py", line 558, in query
    self._affected_rows = self._read_query_result(unbuffered=unbuffered)
  File "C:\Users\user\Desktop\program\Reinforcement_learninng\lib\site-packages\pymysql\connections.py", line 822, in _read_query_result
    result.read()
  File "C:\Users\user\Desktop\program\Reinforcement_learninng\lib\site-packages\pymysql\connections.py", line 1200, in read
    first_packet = self.connection._read_packet()
  File "C:\Users\user\Desktop\program\Reinforcement_learninng\lib\site-packages\pymysql\connections.py", line 772, in _read_packet
    packet.raise_for_error()
  File "C:\Users\user\Desktop\program\Reinforcement_learninng\lib\site-packages\pymysql\protocol.py", line 221, in raise_for_error
    err.raise_mysql_exception(self._data)
  File "C:\Users\user\Desktop\program\Reinforcement_learninng\lib\site-packages\pymysql\err.py", line 143, in raise_mysql_exception
    raise errorclass(errno, errval)
sqlalchemy.exc.ProgrammingError: (pymysql.err.ProgrammingError) (1064, "You have an error in your SQL syntax; check the manual that corresponds to your MySQL server version for the right syntax to use near 'VALUES ('1','2024-02-02 16:08:28.761521')' at line 1")
[SQL: update `interval_record` VALUES ('1','2024-02-02 16:08:28.761521');]
(Background on this error at: https://sqlalche.me/e/20/f405)

