2024-02-05 14:41 ERROR Traceback (most recent call last):
  File "c:\Users\user\Desktop\program\Reinforcement_learninng\finrl_achieve\project\New_Trading_Systeam.py", line 222, in main
    self.check_money_level()
AttributeError: 'AsyncTrading_system' object has no attribute 'check_money_level'

2024-02-05 15:32 ERROR Traceback (most recent call last):
  File "c:\Users\user\Desktop\program\Reinforcement_learninng\finrl_achieve\project\New_Trading_Systeam.py", line 231, in main
    last_status = self.engine.get_order(finally_df, balance_balance_map,leverage = 1)
  File "c:\Users\user\Desktop\program\Reinforcement_learninng\finrl_achieve\project\EIIE\lib\engine.py", line 69, in get_order
    for key,value in balance_balance_map:
ValueError: too many values to unpack (expected 2)

2024-02-05 15:45 ERROR Traceback (most recent call last):
  File "C:\Users\user\Desktop\program\Reinforcement_learninng\lib\site-packages\pandas\core\indexes\base.py", line 3802, in get_loc
    return self._engine.get_loc(casted_key)
  File "index.pyx", line 153, in pandas._libs.index.IndexEngine.get_loc
  File "index.pyx", line 182, in pandas._libs.index.IndexEngine.get_loc
  File "pandas\\_libs\\hashtable_class_helper.pxi", line 7081, in pandas._libs.hashtable.PyObjectHashTable.get_item
  File "pandas\\_libs\\hashtable_class_helper.pxi", line 7089, in pandas._libs.hashtable.PyObjectHashTable.get_item
KeyError: 'tic'

The above exception was the direct cause of the following exception:

Traceback (most recent call last):
  File "c:\Users\user\Desktop\program\Reinforcement_learninng\finrl_achieve\project\New_Trading_Systeam.py", line 237, in main
    last_status = self.engine.get_order(
  File "c:\Users\user\Desktop\program\Reinforcement_learninng\finrl_achieve\project\EIIE\lib\engine.py", line 74, in get_order
    shares = value * weight * leverage  /  last_df[last_df['tic'] == symbol]['close'].iloc[0]
  File "C:\Users\user\Desktop\program\Reinforcement_learninng\lib\site-packages\pandas\core\frame.py", line 4090, in __getitem__
    indexer = self.columns.get_loc(key)
  File "C:\Users\user\Desktop\program\Reinforcement_learninng\lib\site-packages\pandas\core\indexes\base.py", line 3809, in get_loc
    raise KeyError(key) from err
KeyError: 'tic'

2024-02-05 15:48 ERROR Traceback (most recent call last):
  File "c:\Users\user\Desktop\program\Reinforcement_learninng\finrl_achieve\project\New_Trading_Systeam.py", line 237, in main
    last_status = self.engine.get_order(
  File "c:\Users\user\Desktop\program\Reinforcement_learninng\finrl_achieve\project\EIIE\lib\engine.py", line 81, in get_order
    out_map[key].update({symbol:[1,shares]})
KeyError: '0986838449'

2024-02-05 16:04 ERROR Traceback (most recent call last):
  File "c:\Users\user\Desktop\program\Reinforcement_learninng\finrl_achieve\project\New_Trading_Systeam.py", line 266, in main
    all_order_finally, current_size=current_size, symbol_map=self.symbol_map, formal=AppSetting.get_trading_permission()['execute_orders'])
AttributeError: type object 'AppSetting' has no attribute 'get_trading_permission'

2024-02-05 16:07 ERROR Traceback (most recent call last):
  File "c:\Users\user\Desktop\program\Reinforcement_learninng\finrl_achieve\project\New_Trading_Systeam.py", line 265, in main
  File "c:\Users\user\Desktop\program\Reinforcement_learninng\finrl_achieve\project\Major\custom.py", line 52, in wrapper
    new_args = (copy.deepcopy(args[0])[ID_phonenumber],)
KeyError: '0975730876'

2024-02-05 16:15 ERROR Traceback (most recent call last):
  File "c:\Users\user\Desktop\program\Reinforcement_learninng\finrl_achieve\project\New_Trading_Systeam.py", line 272, in main
    if self.dataprovider.Binanceapp.trade_count > AppSetting.get_emergency_times():
AttributeError: type object 'AppSetting' has no attribute 'get_emergency_times'

