2024-03-12 09:11 ERROR Traceback (most recent call last):
  File "c:\Users\user\Desktop\program\Reinforcement_learninng\finrl_achieve\project\TradingSysteam.py", line 244, in main
    if_order_map = self.DQN_engin.get_if_order_map(finally_df)
  File "c:\Users\user\Desktop\program\Reinforcement_learninng\finrl_achieve\project\DQN\lib\engine.py", line 20, in get_if_order_map
    re_evaluate = RL_evaluate(each_strategy)
  File "c:\Users\user\Desktop\program\Reinforcement_learninng\finrl_achieve\project\DQN\lib\Backtest.py", line 91, in __init__
    self.test()
  File "c:\Users\user\Desktop\program\Reinforcement_learninng\finrl_achieve\project\DQN\lib\Backtest.py", line 112, in test
    action = self.agent(state)
  File "C:\Users\user\Desktop\program\Reinforcement_learninng\lib\site-packages\torch\nn\modules\module.py", line 1518, in _wrapped_call_impl
    return self._call_impl(*args, **kwargs)
  File "C:\Users\user\Desktop\program\Reinforcement_learninng\lib\site-packages\torch\nn\modules\module.py", line 1527, in _call_impl
    return forward_call(*args, **kwargs)
  File "c:\Users\user\Desktop\program\Reinforcement_learninng\finrl_achieve\project\DQN\lib\models.py", line 64, in forward
    conv_out = self.conv(x).view(x.size()[0], -1) #執行flatten的動作
  File "C:\Users\user\Desktop\program\Reinforcement_learninng\lib\site-packages\torch\nn\modules\module.py", line 1518, in _wrapped_call_impl
    return self._call_impl(*args, **kwargs)
  File "C:\Users\user\Desktop\program\Reinforcement_learninng\lib\site-packages\torch\nn\modules\module.py", line 1527, in _call_impl
    return forward_call(*args, **kwargs)
  File "C:\Users\user\Desktop\program\Reinforcement_learninng\lib\site-packages\torch\nn\modules\container.py", line 215, in forward
    input = module(input)
  File "C:\Users\user\Desktop\program\Reinforcement_learninng\lib\site-packages\torch\nn\modules\module.py", line 1518, in _wrapped_call_impl
    return self._call_impl(*args, **kwargs)
  File "C:\Users\user\Desktop\program\Reinforcement_learninng\lib\site-packages\torch\nn\modules\module.py", line 1527, in _call_impl
    return forward_call(*args, **kwargs)
  File "C:\Users\user\Desktop\program\Reinforcement_learninng\lib\site-packages\torch\nn\modules\conv.py", line 310, in forward
    return self._conv_forward(input, self.weight, self.bias)
  File "C:\Users\user\Desktop\program\Reinforcement_learninng\lib\site-packages\torch\nn\modules\conv.py", line 306, in _conv_forward
    return F.conv1d(input, weight, bias, self.stride,
RuntimeError: Expected all tensors to be on the same device, but found at least two devices, cpu and cuda:0! (when checking argument for argument weight in method wrapper_CUDA___slow_conv2d_forward)

2024-03-12 11:05 ERROR Traceback (most recent call last):
  File "c:\Users\user\Desktop\program\Reinforcement_learninng\finrl_achieve\project\TradingSysteam.py", line 289, in main
    raise ExcessiveTradeException("當前交易次數超過最大限制")
utils.Debug_tool.ExcessiveTradeException: 當前交易次數超過最大限制

2024-03-12 11:06 ERROR Unclosed client session
client_session: <aiohttp.client.ClientSession object at 0x0000024D4A164B50>
2024-03-12 15:36 ERROR Traceback (most recent call last):
  File "c:\Users\user\Desktop\program\Reinforcement_learninng\finrl_achieve\project\Database\SQL_operate.py", line 13, in get_db_data
    self.userconn = router.Router().mysql_conn
  File "c:\Users\user\Desktop\program\Reinforcement_learninng\finrl_achieve\project\Database\router.py", line 13, in __init__
    self._mysql_conn = self.get_mysql_conn()
  File "c:\Users\user\Desktop\program\Reinforcement_learninng\finrl_achieve\project\Database\router.py", line 28, in get_mysql_conn
    connect = engine.connect()
  File "C:\Users\user\Desktop\program\Reinforcement_learninng\lib\site-packages\sqlalchemy\engine\base.py", line 3268, in connect
    return self._connection_cls(self)
  File "C:\Users\user\Desktop\program\Reinforcement_learninng\lib\site-packages\sqlalchemy\engine\base.py", line 145, in __init__
    self._dbapi_connection = engine.raw_connection()
  File "C:\Users\user\Desktop\program\Reinforcement_learninng\lib\site-packages\sqlalchemy\engine\base.py", line 3292, in raw_connection
    return self.pool.connect()
  File "C:\Users\user\Desktop\program\Reinforcement_learninng\lib\site-packages\sqlalchemy\pool\base.py", line 452, in connect
    return _ConnectionFairy._checkout(self)
  File "C:\Users\user\Desktop\program\Reinforcement_learninng\lib\site-packages\sqlalchemy\pool\base.py", line 1269, in _checkout
    fairy = _ConnectionRecord.checkout(pool)
  File "C:\Users\user\Desktop\program\Reinforcement_learninng\lib\site-packages\sqlalchemy\pool\base.py", line 716, in checkout
    rec = pool._do_get()
  File "C:\Users\user\Desktop\program\Reinforcement_learninng\lib\site-packages\sqlalchemy\pool\impl.py", line 169, in _do_get
    with util.safe_reraise():
  File "C:\Users\user\Desktop\program\Reinforcement_learninng\lib\site-packages\sqlalchemy\util\langhelpers.py", line 146, in __exit__
    raise exc_value.with_traceback(exc_tb)
  File "C:\Users\user\Desktop\program\Reinforcement_learninng\lib\site-packages\sqlalchemy\pool\impl.py", line 167, in _do_get
    return self._create_connection()
  File "C:\Users\user\Desktop\program\Reinforcement_learninng\lib\site-packages\sqlalchemy\pool\base.py", line 393, in _create_connection
    return _ConnectionRecord(self)
  File "C:\Users\user\Desktop\program\Reinforcement_learninng\lib\site-packages\sqlalchemy\pool\base.py", line 678, in __init__
    self.__connect()
  File "C:\Users\user\Desktop\program\Reinforcement_learninng\lib\site-packages\sqlalchemy\pool\base.py", line 902, in __connect
    with util.safe_reraise():
  File "C:\Users\user\Desktop\program\Reinforcement_learninng\lib\site-packages\sqlalchemy\util\langhelpers.py", line 146, in __exit__
    raise exc_value.with_traceback(exc_tb)
  File "C:\Users\user\Desktop\program\Reinforcement_learninng\lib\site-packages\sqlalchemy\pool\base.py", line 898, in __connect
    self.dbapi_connection = connection = pool._invoke_creator(self)
  File "C:\Users\user\Desktop\program\Reinforcement_learninng\lib\site-packages\sqlalchemy\engine\create.py", line 637, in connect
    return dialect.connect(*cargs, **cparams)
  File "C:\Users\user\Desktop\program\Reinforcement_learninng\lib\site-packages\sqlalchemy\engine\default.py", line 616, in connect
    return self.loaded_dbapi.connect(*cargs, **cparams)
  File "C:\Users\user\Desktop\program\Reinforcement_learninng\lib\site-packages\pymysql\connections.py", line 358, in __init__
    self.connect()
  File "C:\Users\user\Desktop\program\Reinforcement_learninng\lib\site-packages\pymysql\connections.py", line 664, in connect
    self._request_authentication()
  File "C:\Users\user\Desktop\program\Reinforcement_learninng\lib\site-packages\pymysql\connections.py", line 976, in _request_authentication
    auth_packet = _auth.caching_sha2_password_auth(self, auth_packet)
  File "C:\Users\user\Desktop\program\Reinforcement_learninng\lib\site-packages\pymysql\_auth.py", line 266, in caching_sha2_password_auth
    data = sha2_rsa_encrypt(conn.password, conn.salt, conn.server_public_key)
  File "C:\Users\user\Desktop\program\Reinforcement_learninng\lib\site-packages\pymysql\_auth.py", line 143, in sha2_rsa_encrypt
    raise RuntimeError(
RuntimeError: 'cryptography' package is required for sha256_password or caching_sha2_password auth methods

