2024-07-27 12:33 ERROR Traceback (most recent call last):
  File "c:\Users\Wour\Desktop\Program\finrl_achieve\project\TradingSysteam.py", line 265, in main
    self.DQN_engin.strategy_prepare(self.targetsymbols)
  File "c:\Users\Wour\Desktop\Program\finrl_achieve\project\DQN\lib\engine.py", line 57, in strategy_prepare
    self.strategys.append(self.creaet_strategy(Meta_model_path, symbol=symbol))
TypeError: EngineBase.creaet_strategy() got an unexpected keyword argument 'symbol'

2024-07-27 12:41 ERROR Traceback (most recent call last):
  File "c:\Users\Wour\Desktop\Program\finrl_achieve\project\TradingSysteam.py", line 265, in main
    self.DQN_engin.strategy_prepare(self.targetsymbols)
  File "c:\Users\Wour\Desktop\Program\finrl_achieve\project\DQN\lib\engine.py", line 60, in strategy_prepare
    self.strategys.append(self.creaet_strategy(Meta_model_path, symbol=symbol))
AttributeError: 'EngineBase' object has no attribute 'creaet_strategy'. Did you mean: 'create_strategy'?

2024-07-27 13:39 ERROR Traceback (most recent call last):
  File "c:\Users\Wour\Desktop\Program\finrl_achieve\project\Database\SQL_operate.py", line 13, in get_db_data
    self.userconn = router.Router().mysql_conn
  File "c:\Users\Wour\Desktop\Program\finrl_achieve\project\Database\router.py", line 13, in __init__
    self._mysql_conn = self.get_mysql_conn()
  File "c:\Users\Wour\Desktop\Program\finrl_achieve\project\Database\router.py", line 28, in get_mysql_conn
    connect = engine.connect()
  File "C:\Users\Wour\AppData\Roaming\Python\Python310\site-packages\sqlalchemy\engine\base.py", line 3268, in connect
    return self._connection_cls(self)
  File "C:\Users\Wour\AppData\Roaming\Python\Python310\site-packages\sqlalchemy\engine\base.py", line 145, in __init__
    self._dbapi_connection = engine.raw_connection()
  File "C:\Users\Wour\AppData\Roaming\Python\Python310\site-packages\sqlalchemy\engine\base.py", line 3292, in raw_connection
    return self.pool.connect()
  File "C:\Users\Wour\AppData\Roaming\Python\Python310\site-packages\sqlalchemy\pool\base.py", line 452, in connect
    return _ConnectionFairy._checkout(self)
  File "C:\Users\Wour\AppData\Roaming\Python\Python310\site-packages\sqlalchemy\pool\base.py", line 1269, in _checkout
    fairy = _ConnectionRecord.checkout(pool)
  File "C:\Users\Wour\AppData\Roaming\Python\Python310\site-packages\sqlalchemy\pool\base.py", line 716, in checkout
    rec = pool._do_get()
  File "C:\Users\Wour\AppData\Roaming\Python\Python310\site-packages\sqlalchemy\pool\impl.py", line 169, in _do_get
    with util.safe_reraise():
  File "C:\Users\Wour\AppData\Roaming\Python\Python310\site-packages\sqlalchemy\util\langhelpers.py", line 146, in __exit__
    raise exc_value.with_traceback(exc_tb)
  File "C:\Users\Wour\AppData\Roaming\Python\Python310\site-packages\sqlalchemy\pool\impl.py", line 167, in _do_get
    return self._create_connection()
  File "C:\Users\Wour\AppData\Roaming\Python\Python310\site-packages\sqlalchemy\pool\base.py", line 393, in _create_connection
    return _ConnectionRecord(self)
  File "C:\Users\Wour\AppData\Roaming\Python\Python310\site-packages\sqlalchemy\pool\base.py", line 678, in __init__
    self.__connect()
  File "C:\Users\Wour\AppData\Roaming\Python\Python310\site-packages\sqlalchemy\pool\base.py", line 902, in __connect
    with util.safe_reraise():
  File "C:\Users\Wour\AppData\Roaming\Python\Python310\site-packages\sqlalchemy\util\langhelpers.py", line 146, in __exit__
    raise exc_value.with_traceback(exc_tb)
  File "C:\Users\Wour\AppData\Roaming\Python\Python310\site-packages\sqlalchemy\pool\base.py", line 898, in __connect
    self.dbapi_connection = connection = pool._invoke_creator(self)
  File "C:\Users\Wour\AppData\Roaming\Python\Python310\site-packages\sqlalchemy\engine\create.py", line 637, in connect
    return dialect.connect(*cargs, **cparams)
  File "C:\Users\Wour\AppData\Roaming\Python\Python310\site-packages\sqlalchemy\engine\default.py", line 616, in connect
    return self.loaded_dbapi.connect(*cargs, **cparams)
  File "C:\Users\Wour\AppData\Roaming\Python\Python310\site-packages\pymysql\connections.py", line 358, in __init__
    self.connect()
  File "C:\Users\Wour\AppData\Roaming\Python\Python310\site-packages\pymysql\connections.py", line 664, in connect
    self._request_authentication()
  File "C:\Users\Wour\AppData\Roaming\Python\Python310\site-packages\pymysql\connections.py", line 976, in _request_authentication
    auth_packet = _auth.caching_sha2_password_auth(self, auth_packet)
  File "C:\Users\Wour\AppData\Roaming\Python\Python310\site-packages\pymysql\_auth.py", line 266, in caching_sha2_password_auth
    data = sha2_rsa_encrypt(conn.password, conn.salt, conn.server_public_key)
  File "C:\Users\Wour\AppData\Roaming\Python\Python310\site-packages\pymysql\_auth.py", line 143, in sha2_rsa_encrypt
    raise RuntimeError(
RuntimeError: 'cryptography' package is required for sha256_password or caching_sha2_password auth methods

2024-07-27 17:43 ERROR Traceback (most recent call last):
  File "c:\Users\Wour\Desktop\Program\finrl_achieve\project\Database\SQL_operate.py", line 13, in get_db_data
    self.userconn = router.Router().mysql_conn
  File "c:\Users\Wour\Desktop\Program\finrl_achieve\project\Database\router.py", line 13, in __init__
    self._mysql_conn = self.get_mysql_conn()
  File "c:\Users\Wour\Desktop\Program\finrl_achieve\project\Database\router.py", line 28, in get_mysql_conn
    connect = engine.connect()
  File "C:\Users\Wour\AppData\Roaming\Python\Python310\site-packages\sqlalchemy\engine\base.py", line 3268, in connect
    return self._connection_cls(self)
  File "C:\Users\Wour\AppData\Roaming\Python\Python310\site-packages\sqlalchemy\engine\base.py", line 145, in __init__
    self._dbapi_connection = engine.raw_connection()
  File "C:\Users\Wour\AppData\Roaming\Python\Python310\site-packages\sqlalchemy\engine\base.py", line 3292, in raw_connection
    return self.pool.connect()
  File "C:\Users\Wour\AppData\Roaming\Python\Python310\site-packages\sqlalchemy\pool\base.py", line 452, in connect
    return _ConnectionFairy._checkout(self)
  File "C:\Users\Wour\AppData\Roaming\Python\Python310\site-packages\sqlalchemy\pool\base.py", line 1269, in _checkout
    fairy = _ConnectionRecord.checkout(pool)
  File "C:\Users\Wour\AppData\Roaming\Python\Python310\site-packages\sqlalchemy\pool\base.py", line 716, in checkout
    rec = pool._do_get()
  File "C:\Users\Wour\AppData\Roaming\Python\Python310\site-packages\sqlalchemy\pool\impl.py", line 169, in _do_get
    with util.safe_reraise():
  File "C:\Users\Wour\AppData\Roaming\Python\Python310\site-packages\sqlalchemy\util\langhelpers.py", line 146, in __exit__
    raise exc_value.with_traceback(exc_tb)
  File "C:\Users\Wour\AppData\Roaming\Python\Python310\site-packages\sqlalchemy\pool\impl.py", line 167, in _do_get
    return self._create_connection()
  File "C:\Users\Wour\AppData\Roaming\Python\Python310\site-packages\sqlalchemy\pool\base.py", line 393, in _create_connection
    return _ConnectionRecord(self)
  File "C:\Users\Wour\AppData\Roaming\Python\Python310\site-packages\sqlalchemy\pool\base.py", line 678, in __init__
    self.__connect()
  File "C:\Users\Wour\AppData\Roaming\Python\Python310\site-packages\sqlalchemy\pool\base.py", line 902, in __connect
    with util.safe_reraise():
  File "C:\Users\Wour\AppData\Roaming\Python\Python310\site-packages\sqlalchemy\util\langhelpers.py", line 146, in __exit__
    raise exc_value.with_traceback(exc_tb)
  File "C:\Users\Wour\AppData\Roaming\Python\Python310\site-packages\sqlalchemy\pool\base.py", line 898, in __connect
    self.dbapi_connection = connection = pool._invoke_creator(self)
  File "C:\Users\Wour\AppData\Roaming\Python\Python310\site-packages\sqlalchemy\engine\create.py", line 637, in connect
    return dialect.connect(*cargs, **cparams)
  File "C:\Users\Wour\AppData\Roaming\Python\Python310\site-packages\sqlalchemy\engine\default.py", line 616, in connect
    return self.loaded_dbapi.connect(*cargs, **cparams)
  File "C:\Users\Wour\AppData\Roaming\Python\Python310\site-packages\pymysql\connections.py", line 358, in __init__
    self.connect()
  File "C:\Users\Wour\AppData\Roaming\Python\Python310\site-packages\pymysql\connections.py", line 664, in connect
    self._request_authentication()
  File "C:\Users\Wour\AppData\Roaming\Python\Python310\site-packages\pymysql\connections.py", line 976, in _request_authentication
    auth_packet = _auth.caching_sha2_password_auth(self, auth_packet)
  File "C:\Users\Wour\AppData\Roaming\Python\Python310\site-packages\pymysql\_auth.py", line 266, in caching_sha2_password_auth
    data = sha2_rsa_encrypt(conn.password, conn.salt, conn.server_public_key)
  File "C:\Users\Wour\AppData\Roaming\Python\Python310\site-packages\pymysql\_auth.py", line 143, in sha2_rsa_encrypt
    raise RuntimeError(
RuntimeError: 'cryptography' package is required for sha256_password or caching_sha2_password auth methods

2024-07-28 03:52 ERROR Traceback (most recent call last):
  File "C:\ProgramData\anaconda3\envs\RL_trading\lib\site-packages\urllib3\connectionpool.py", line 536, in _make_request
    response = conn.getresponse()
  File "C:\ProgramData\anaconda3\envs\RL_trading\lib\site-packages\urllib3\connection.py", line 464, in getresponse
    httplib_response = super().getresponse()
  File "C:\ProgramData\anaconda3\envs\RL_trading\lib\http\client.py", line 1375, in getresponse
    response.begin()
  File "C:\ProgramData\anaconda3\envs\RL_trading\lib\http\client.py", line 318, in begin
    version, status, reason = self._read_status()
  File "C:\ProgramData\anaconda3\envs\RL_trading\lib\http\client.py", line 279, in _read_status
    line = str(self.fp.readline(_MAXLINE + 1), "iso-8859-1")
  File "C:\ProgramData\anaconda3\envs\RL_trading\lib\socket.py", line 705, in readinto
    return self._sock.recv_into(b)
  File "C:\ProgramData\anaconda3\envs\RL_trading\lib\ssl.py", line 1307, in recv_into
    return self.read(nbytes, buffer)
  File "C:\ProgramData\anaconda3\envs\RL_trading\lib\ssl.py", line 1163, in read
    return self._sslobj.read(len, buffer)
TimeoutError: The read operation timed out

The above exception was the direct cause of the following exception:

Traceback (most recent call last):
  File "C:\ProgramData\anaconda3\envs\RL_trading\lib\site-packages\requests\adapters.py", line 589, in send
    resp = conn.urlopen(
  File "C:\ProgramData\anaconda3\envs\RL_trading\lib\site-packages\urllib3\connectionpool.py", line 843, in urlopen
    retries = retries.increment(
  File "C:\ProgramData\anaconda3\envs\RL_trading\lib\site-packages\urllib3\util\retry.py", line 474, in increment
    raise reraise(type(error), error, _stacktrace)
  File "C:\ProgramData\anaconda3\envs\RL_trading\lib\site-packages\urllib3\util\util.py", line 39, in reraise
    raise value
  File "C:\ProgramData\anaconda3\envs\RL_trading\lib\site-packages\urllib3\connectionpool.py", line 789, in urlopen
    response = self._make_request(
  File "C:\ProgramData\anaconda3\envs\RL_trading\lib\site-packages\urllib3\connectionpool.py", line 538, in _make_request
    self._raise_timeout(err=e, url=url, timeout_value=read_timeout)
  File "C:\ProgramData\anaconda3\envs\RL_trading\lib\site-packages\urllib3\connectionpool.py", line 369, in _raise_timeout
    raise ReadTimeoutError(
urllib3.exceptions.ReadTimeoutError: HTTPSConnectionPool(host='fapi.binance.com', port=443): Read timed out. (read timeout=10)

During handling of the above exception, another exception occurred:

Traceback (most recent call last):
  File "c:\Users\Wour\Desktop\Program\finrl_achieve\project\Major\DataProvider.py", line 101, in reload_all_data
    original_df, eachCatchDf = self.reload_data(
  File "c:\Users\Wour\Desktop\Program\finrl_achieve\project\Major\DataProvider.py", line 62, in reload_data
    original_df, eachCatchDf = self.Binanceapp.BinanceDate.download(
  File "c:\Users\Wour\Desktop\Program\finrl_achieve\project\Major\custom.py", line 42, in wrapper
    result = func(self, client, *args, **kwargs)
  File "c:\Users\Wour\Desktop\Program\finrl_achieve\project\Major\custom.py", line 240, in download
    klines = cls.historicalklines(symbol, kline_size, oldest_point.strftime("%d %b %Y %H:%M:%S"),
  File "c:\Users\Wour\Desktop\Program\finrl_achieve\project\Major\custom.py", line 118, in historicalklines
    temp_data = client._klines(
  File "C:\Users\Wour\AppData\Roaming\Python\Python310\site-packages\binance\client.py", line 936, in _klines
    return self.futures_klines(**params)
  File "C:\Users\Wour\AppData\Roaming\Python\Python310\site-packages\binance\client.py", line 6202, in futures_klines
    return self._request_futures_api('get', 'klines', data=params)
  File "C:\Users\Wour\AppData\Roaming\Python\Python310\site-packages\binance\client.py", line 383, in _request_futures_api
    return self._request(method, uri, signed, True, **kwargs)
  File "C:\Users\Wour\AppData\Roaming\Python\Python310\site-packages\binance\client.py", line 358, in _request
    self.response = getattr(self.session, method)(uri, **kwargs)
  File "C:\ProgramData\anaconda3\envs\RL_trading\lib\site-packages\requests\sessions.py", line 602, in get
    return self.request("GET", url, **kwargs)
  File "C:\ProgramData\anaconda3\envs\RL_trading\lib\site-packages\requests\sessions.py", line 589, in request
    resp = self.send(prep, **send_kwargs)
  File "C:\ProgramData\anaconda3\envs\RL_trading\lib\site-packages\requests\sessions.py", line 703, in send
    r = adapter.send(request, **kwargs)
  File "C:\ProgramData\anaconda3\envs\RL_trading\lib\site-packages\requests\adapters.py", line 635, in send
    raise ReadTimeout(e, request=request)
requests.exceptions.ReadTimeout: HTTPSConnectionPool(host='fapi.binance.com', port=443): Read timed out. (read timeout=10)

2024-07-28 03:52 ERROR symbol = NKNUSDT
