2024-02-06 07:56 ERROR Traceback (most recent call last):
  File "c:\Users\user\Desktop\program\Reinforcement_learninng\finrl_achieve\project\Database\SQL_operate.py", line 13, in get_db_data
    self.userconn = router.Router().mysql_conn
  File "c:\Users\user\Desktop\program\Reinforcement_learninng\finrl_achieve\project\Database\router.py", line 13, in __init__
    self._mysql_conn = self.get_mysql_conn()
  File "c:\Users\user\Desktop\program\Reinforcement_learninng\finrl_achieve\project\Database\router.py", line 28, in get_mysql_conn
    connect = engine.connect()
  File "C:\Users\user\Desktop\program\Reinforcement_learninng\lib\site-packages\sqlalchemy\engine\base.py", line 3268, in connect
    return self._connection_cls(self)
  File "C:\Users\user\Desktop\program\Reinforcement_learninng\lib\site-packages\sqlalchemy\engine\base.py", line 145, in __init__
    self._dbapi_connection = engine.raw_connection()
  File "C:\Users\user\Desktop\program\Reinforcement_learninng\lib\site-packages\sqlalchemy\engine\base.py", line 3292, in raw_connection
    return self.pool.connect()
  File "C:\Users\user\Desktop\program\Reinforcement_learninng\lib\site-packages\sqlalchemy\pool\base.py", line 452, in connect
    return _ConnectionFairy._checkout(self)
  File "C:\Users\user\Desktop\program\Reinforcement_learninng\lib\site-packages\sqlalchemy\pool\base.py", line 1269, in _checkout
    fairy = _ConnectionRecord.checkout(pool)
  File "C:\Users\user\Desktop\program\Reinforcement_learninng\lib\site-packages\sqlalchemy\pool\base.py", line 716, in checkout
    rec = pool._do_get()
  File "C:\Users\user\Desktop\program\Reinforcement_learninng\lib\site-packages\sqlalchemy\pool\impl.py", line 169, in _do_get
    with util.safe_reraise():
  File "C:\Users\user\Desktop\program\Reinforcement_learninng\lib\site-packages\sqlalchemy\util\langhelpers.py", line 146, in __exit__
    raise exc_value.with_traceback(exc_tb)
  File "C:\Users\user\Desktop\program\Reinforcement_learninng\lib\site-packages\sqlalchemy\pool\impl.py", line 167, in _do_get
    return self._create_connection()
  File "C:\Users\user\Desktop\program\Reinforcement_learninng\lib\site-packages\sqlalchemy\pool\base.py", line 393, in _create_connection
    return _ConnectionRecord(self)
  File "C:\Users\user\Desktop\program\Reinforcement_learninng\lib\site-packages\sqlalchemy\pool\base.py", line 678, in __init__
    self.__connect()
  File "C:\Users\user\Desktop\program\Reinforcement_learninng\lib\site-packages\sqlalchemy\pool\base.py", line 902, in __connect
    with util.safe_reraise():
  File "C:\Users\user\Desktop\program\Reinforcement_learninng\lib\site-packages\sqlalchemy\util\langhelpers.py", line 146, in __exit__
    raise exc_value.with_traceback(exc_tb)
  File "C:\Users\user\Desktop\program\Reinforcement_learninng\lib\site-packages\sqlalchemy\pool\base.py", line 898, in __connect
    self.dbapi_connection = connection = pool._invoke_creator(self)
  File "C:\Users\user\Desktop\program\Reinforcement_learninng\lib\site-packages\sqlalchemy\engine\create.py", line 637, in connect
    return dialect.connect(*cargs, **cparams)
  File "C:\Users\user\Desktop\program\Reinforcement_learninng\lib\site-packages\sqlalchemy\engine\default.py", line 616, in connect
    return self.loaded_dbapi.connect(*cargs, **cparams)
  File "C:\Users\user\Desktop\program\Reinforcement_learninng\lib\site-packages\pymysql\connections.py", line 358, in __init__
    self.connect()
  File "C:\Users\user\Desktop\program\Reinforcement_learninng\lib\site-packages\pymysql\connections.py", line 664, in connect
    self._request_authentication()
  File "C:\Users\user\Desktop\program\Reinforcement_learninng\lib\site-packages\pymysql\connections.py", line 976, in _request_authentication
    auth_packet = _auth.caching_sha2_password_auth(self, auth_packet)
  File "C:\Users\user\Desktop\program\Reinforcement_learninng\lib\site-packages\pymysql\_auth.py", line 266, in caching_sha2_password_auth
    data = sha2_rsa_encrypt(conn.password, conn.salt, conn.server_public_key)
  File "C:\Users\user\Desktop\program\Reinforcement_learninng\lib\site-packages\pymysql\_auth.py", line 143, in sha2_rsa_encrypt
    raise RuntimeError(
RuntimeError: 'cryptography' package is required for sha256_password or caching_sha2_password auth methods

2024-02-06 09:12 ERROR System crashed, restart the program.
2024-02-06 09:29 ERROR Traceback (most recent call last):
  File "C:\Users\user\Desktop\program\Reinforcement_learninng\finrl_achieve\project\TradingSysteam.py", line 239, in main
    raise ValueError("錯誤系統測試")
ValueError: 錯誤系統測試

2024-02-06 09:44 ERROR Traceback (most recent call last):
  File "C:\Users\user\Desktop\program\Reinforcement_learninng\finrl_achieve\project\TradingSysteam.py", line 239, in main
    raise ValueError("錯誤系統測試")
ValueError: 錯誤系統測試

2024-02-06 09:48 ERROR Traceback (most recent call last):
  File "C:\Users\user\Desktop\program\Reinforcement_learninng\finrl_achieve\project\TradingSysteam.py", line 239, in main
    raise ValueError("錯誤系統測試")
ValueError: 錯誤系統測試

2024-02-06 09:51 ERROR Traceback (most recent call last):
  File "C:\Users\user\Desktop\program\Reinforcement_learninng\finrl_achieve\project\TradingSysteam.py", line 239, in main
    raise ValueError("錯誤系統測試")
ValueError: 錯誤系統測試

2024-02-06 09:51 ERROR System crashed, restart the program.
2024-02-06 09:52 ERROR Traceback (most recent call last):
  File "C:\Users\user\Desktop\program\Reinforcement_learninng\finrl_achieve\project\TradingSysteam.py", line 239, in main
    raise ValueError("錯誤系統測試")
ValueError: 錯誤系統測試

2024-02-06 10:15 ERROR Traceback (most recent call last):
  File "c:\Users\user\Desktop\program\Reinforcement_learninng\finrl_achieve\project\TradingSysteam.py", line 241, in main
    raise ValueError("錯誤系統測試")
ValueError: 錯誤系統測試

2024-02-06 10:18 ERROR Traceback (most recent call last):
  File "c:\Users\user\Desktop\program\Reinforcement_learninng\finrl_achieve\project\TradingSysteam.py", line 241, in main
    raise ValueError("錯誤系統測試")
ValueError: 錯誤系統測試

2024-02-06 10:20 ERROR Traceback (most recent call last):
  File "c:\Users\user\Desktop\program\Reinforcement_learninng\finrl_achieve\project\TradingSysteam.py", line 241, in main
    raise ValueError("錯誤系統測試")
ValueError: 錯誤系統測試

2024-02-06 10:21 ERROR Traceback (most recent call last):
  File "c:\Users\user\Desktop\program\Reinforcement_learninng\finrl_achieve\project\TradingSysteam.py", line 241, in main
    raise ValueError("錯誤系統測試")
ValueError: 錯誤系統測試

2024-02-06 10:21 ERROR Unclosed client session
client_session: <aiohttp.client.ClientSession object at 0x0000022704B23550>
2024-02-06 10:23 ERROR Traceback (most recent call last):
  File "C:\Users\user\Desktop\program\Reinforcement_learninng\finrl_achieve\project\TradingSysteam.py", line 241, in main
    raise ValueError("錯誤系統測試")
ValueError: 錯誤系統測試

2024-02-06 10:23 ERROR Unclosed client session
client_session: <aiohttp.client.ClientSession object at 0x000001F236F8BA00>
2024-02-06 10:24 ERROR System crashed, restart the program.
2024-02-06 10:32 ERROR Traceback (most recent call last):
  File "c:\Users\user\Desktop\program\Reinforcement_learninng\finrl_achieve\project\TradingSysteam.py", line 240, in main
    raise ExcessiveTradeException("當前交易次數超過最大限制")
utils.Debug_tool.ExcessiveTradeException: 當前交易次數超過最大限制

2024-02-06 10:32 ERROR Unclosed client session
client_session: <aiohttp.client.ClientSession object at 0x000001DF548613C0>
