2024-06-03 11:50 ERROR Traceback (most recent call last):
  File "C:\Users\user\Desktop\program\Reinforcement_learninng\lib\site-packages\sqlalchemy\engine\base.py", line 1969, in _exec_single_context
    self.dialect.do_execute(
  File "C:\Users\user\Desktop\program\Reinforcement_learninng\lib\site-packages\sqlalchemy\engine\default.py", line 922, in do_execute
    cursor.execute(statement, parameters)
  File "C:\Users\user\Desktop\program\Reinforcement_learninng\lib\site-packages\pymysql\cursors.py", line 153, in execute
    result = self._query(query)
  File "C:\Users\user\Desktop\program\Reinforcement_learninng\lib\site-packages\pymysql\cursors.py", line 322, in _query
    conn.query(q)
  File "C:\Users\user\Desktop\program\Reinforcement_learninng\lib\site-packages\pymysql\connections.py", line 558, in query
    self._affected_rows = self._read_query_result(unbuffered=unbuffered)
  File "C:\Users\user\Desktop\program\Reinforcement_learninng\lib\site-packages\pymysql\connections.py", line 822, in _read_query_result
    result.read()
  File "C:\Users\user\Desktop\program\Reinforcement_learninng\lib\site-packages\pymysql\connections.py", line 1200, in read
    first_packet = self.connection._read_packet()
  File "C:\Users\user\Desktop\program\Reinforcement_learninng\lib\site-packages\pymysql\connections.py", line 772, in _read_packet
    packet.raise_for_error()
  File "C:\Users\user\Desktop\program\Reinforcement_learninng\lib\site-packages\pymysql\protocol.py", line 221, in raise_for_error
    err.raise_mysql_exception(self._data)
  File "C:\Users\user\Desktop\program\Reinforcement_learninng\lib\site-packages\pymysql\err.py", line 143, in raise_mysql_exception
    raise errorclass(errno, errval)
pymysql.err.ProgrammingError: (1064, "You have an error in your SQL syntax; check the manual that corresponds to your MySQL server version for the right syntax to use near 'turbousdt-f-d' at line 1")

The above exception was the direct cause of the following exception:

Traceback (most recent call last):
  File "c:\Users\user\Desktop\program\Reinforcement_learninng\finrl_achieve\project\Database\SQL_operate.py", line 48, in read_Dateframe
    return pd.read_sql(text_msg, con=conn)
  File "C:\Users\user\Desktop\program\Reinforcement_learninng\lib\site-packages\pandas\io\sql.py", line 734, in read_sql
    return pandas_sql.read_query(
  File "C:\Users\user\Desktop\program\Reinforcement_learninng\lib\site-packages\pandas\io\sql.py", line 1839, in read_query
    result = self.execute(sql, params)
  File "C:\Users\user\Desktop\program\Reinforcement_learninng\lib\site-packages\pandas\io\sql.py", line 1662, in execute
    return self.con.exec_driver_sql(sql, *args)
  File "C:\Users\user\Desktop\program\Reinforcement_learninng\lib\site-packages\sqlalchemy\engine\base.py", line 1778, in exec_driver_sql
    ret = self._execute_context(
  File "C:\Users\user\Desktop\program\Reinforcement_learninng\lib\site-packages\sqlalchemy\engine\base.py", line 1848, in _execute_context
    return self._exec_single_context(
  File "C:\Users\user\Desktop\program\Reinforcement_learninng\lib\site-packages\sqlalchemy\engine\base.py", line 1988, in _exec_single_context
    self._handle_dbapi_exception(
  File "C:\Users\user\Desktop\program\Reinforcement_learninng\lib\site-packages\sqlalchemy\engine\base.py", line 2343, in _handle_dbapi_exception
    raise sqlalchemy_exception.with_traceback(exc_info[2]) from e
  File "C:\Users\user\Desktop\program\Reinforcement_learninng\lib\site-packages\sqlalchemy\engine\base.py", line 1969, in _exec_single_context
    self.dialect.do_execute(
  File "C:\Users\user\Desktop\program\Reinforcement_learninng\lib\site-packages\sqlalchemy\engine\default.py", line 922, in do_execute
    cursor.execute(statement, parameters)
  File "C:\Users\user\Desktop\program\Reinforcement_learninng\lib\site-packages\pymysql\cursors.py", line 153, in execute
    result = self._query(query)
  File "C:\Users\user\Desktop\program\Reinforcement_learninng\lib\site-packages\pymysql\cursors.py", line 322, in _query
    conn.query(q)
  File "C:\Users\user\Desktop\program\Reinforcement_learninng\lib\site-packages\pymysql\connections.py", line 558, in query
    self._affected_rows = self._read_query_result(unbuffered=unbuffered)
  File "C:\Users\user\Desktop\program\Reinforcement_learninng\lib\site-packages\pymysql\connections.py", line 822, in _read_query_result
    result.read()
  File "C:\Users\user\Desktop\program\Reinforcement_learninng\lib\site-packages\pymysql\connections.py", line 1200, in read
    first_packet = self.connection._read_packet()
  File "C:\Users\user\Desktop\program\Reinforcement_learninng\lib\site-packages\pymysql\connections.py", line 772, in _read_packet
    packet.raise_for_error()
  File "C:\Users\user\Desktop\program\Reinforcement_learninng\lib\site-packages\pymysql\protocol.py", line 221, in raise_for_error
    err.raise_mysql_exception(self._data)
  File "C:\Users\user\Desktop\program\Reinforcement_learninng\lib\site-packages\pymysql\err.py", line 143, in raise_mysql_exception
    raise errorclass(errno, errval)
sqlalchemy.exc.ProgrammingError: (pymysql.err.ProgrammingError) (1064, "You have an error in your SQL syntax; check the manual that corresponds to your MySQL server version for the right syntax to use near 'turbousdt-f-d' at line 1")
[SQL: turbousdt-f-d]
(Background on this error at: https://sqlalche.me/e/20/f405)

