2024-07-26 21:26 ERROR Traceback (most recent call last):
  File "C:\Users\Wour\AppData\Roaming\Python\Python310\site-packages\sqlalchemy\engine\base.py", line 1969, in _exec_single_context
    self.dialect.do_execute(
  File "C:\Users\Wour\AppData\Roaming\Python\Python310\site-packages\sqlalchemy\engine\default.py", line 922, in do_execute
    cursor.execute(statement, parameters)
  File "C:\Users\Wour\AppData\Roaming\Python\Python310\site-packages\pymysql\cursors.py", line 153, in execute
    result = self._query(query)
  File "C:\Users\Wour\AppData\Roaming\Python\Python310\site-packages\pymysql\cursors.py", line 322, in _query
    conn.query(q)
  File "C:\Users\Wour\AppData\Roaming\Python\Python310\site-packages\pymysql\connections.py", line 558, in query
    self._affected_rows = self._read_query_result(unbuffered=unbuffered)
  File "C:\Users\Wour\AppData\Roaming\Python\Python310\site-packages\pymysql\connections.py", line 822, in _read_query_result
    result.read()
  File "C:\Users\Wour\AppData\Roaming\Python\Python310\site-packages\pymysql\connections.py", line 1200, in read
    first_packet = self.connection._read_packet()
  File "C:\Users\Wour\AppData\Roaming\Python\Python310\site-packages\pymysql\connections.py", line 772, in _read_packet
    packet.raise_for_error()
  File "C:\Users\Wour\AppData\Roaming\Python\Python310\site-packages\pymysql\protocol.py", line 221, in raise_for_error
    err.raise_mysql_exception(self._data)
  File "C:\Users\Wour\AppData\Roaming\Python\Python310\site-packages\pymysql\err.py", line 143, in raise_mysql_exception
    raise errorclass(errno, errval)
pymysql.err.ProgrammingError: (1146, "Table 'crypto_data.btcusdt-f-d' doesn't exist")

The above exception was the direct cause of the following exception:

Traceback (most recent call last):
  File "c:\Users\Wour\Desktop\Program\finrl_achieve\project\Database\SQL_operate.py", line 16, in get_db_data
    result = conn.execute(
  File "C:\Users\Wour\AppData\Roaming\Python\Python310\site-packages\sqlalchemy\engine\base.py", line 1416, in execute
    return meth(
  File "C:\Users\Wour\AppData\Roaming\Python\Python310\site-packages\sqlalchemy\sql\elements.py", line 516, in _execute_on_connection
    return connection._execute_clauseelement(
  File "C:\Users\Wour\AppData\Roaming\Python\Python310\site-packages\sqlalchemy\engine\base.py", line 1639, in _execute_clauseelement
    ret = self._execute_context(
  File "C:\Users\Wour\AppData\Roaming\Python\Python310\site-packages\sqlalchemy\engine\base.py", line 1848, in _execute_context
    return self._exec_single_context(
  File "C:\Users\Wour\AppData\Roaming\Python\Python310\site-packages\sqlalchemy\engine\base.py", line 1988, in _exec_single_context
    self._handle_dbapi_exception(
  File "C:\Users\Wour\AppData\Roaming\Python\Python310\site-packages\sqlalchemy\engine\base.py", line 2343, in _handle_dbapi_exception
    raise sqlalchemy_exception.with_traceback(exc_info[2]) from e
  File "C:\Users\Wour\AppData\Roaming\Python\Python310\site-packages\sqlalchemy\engine\base.py", line 1969, in _exec_single_context
    self.dialect.do_execute(
  File "C:\Users\Wour\AppData\Roaming\Python\Python310\site-packages\sqlalchemy\engine\default.py", line 922, in do_execute
    cursor.execute(statement, parameters)
  File "C:\Users\Wour\AppData\Roaming\Python\Python310\site-packages\pymysql\cursors.py", line 153, in execute
    result = self._query(query)
  File "C:\Users\Wour\AppData\Roaming\Python\Python310\site-packages\pymysql\cursors.py", line 322, in _query
    conn.query(q)
  File "C:\Users\Wour\AppData\Roaming\Python\Python310\site-packages\pymysql\connections.py", line 558, in query
    self._affected_rows = self._read_query_result(unbuffered=unbuffered)
  File "C:\Users\Wour\AppData\Roaming\Python\Python310\site-packages\pymysql\connections.py", line 822, in _read_query_result
    result.read()
  File "C:\Users\Wour\AppData\Roaming\Python\Python310\site-packages\pymysql\connections.py", line 1200, in read
    first_packet = self.connection._read_packet()
  File "C:\Users\Wour\AppData\Roaming\Python\Python310\site-packages\pymysql\connections.py", line 772, in _read_packet
    packet.raise_for_error()
  File "C:\Users\Wour\AppData\Roaming\Python\Python310\site-packages\pymysql\protocol.py", line 221, in raise_for_error
    err.raise_mysql_exception(self._data)
  File "C:\Users\Wour\AppData\Roaming\Python\Python310\site-packages\pymysql\err.py", line 143, in raise_mysql_exception
    raise errorclass(errno, errval)
sqlalchemy.exc.ProgrammingError: (pymysql.err.ProgrammingError) (1146, "Table 'crypto_data.btcusdt-f-d' doesn't exist")
[SQL: select *  from `btcusdt-f-d` order by Datetime desc limit 1]
(Background on this error at: https://sqlalche.me/e/20/f405)

