2024-02-04 11:23 ERROR Traceback (most recent call last):
  File "c:\Users\user\Desktop\program\Reinforcement_learninng\finrl_achieve\project\New_Trading_Systeam.py", line 215, in main
    self.dataprovider.get_trade_data(self.symbol_map,freq=self.engine_setting['FREQ_TIME'])
  File "c:\Users\user\Desktop\program\Reinforcement_learninng\finrl_achieve\project\Major\DataProvider.py", line 176, in get_trade_data
    new_df = self.datatransformer.get_tradedata(original_df, freq=freq)
  File "c:\Users\user\Desktop\program\Reinforcement_learninng\finrl_achieve\project\Major\Datatransformer.py", line 25, in get_tradedata
    df.reset_index(inplace=True)
AttributeError: 'dict' object has no attribute 'reset_index'

2024-02-04 12:12 ERROR Traceback (most recent call last):
  File "C:\Users\user\Desktop\program\Reinforcement_learninng\lib\site-packages\pandas\core\indexes\base.py", line 3802, in get_loc
    return self._engine.get_loc(casted_key)
  File "index.pyx", line 153, in pandas._libs.index.IndexEngine.get_loc
  File "index.pyx", line 182, in pandas._libs.index.IndexEngine.get_loc
  File "pandas\\_libs\\hashtable_class_helper.pxi", line 7081, in pandas._libs.hashtable.PyObjectHashTable.get_item
  File "pandas\\_libs\\hashtable_class_helper.pxi", line 7089, in pandas._libs.hashtable.PyObjectHashTable.get_item
KeyError: 'date'

The above exception was the direct cause of the following exception:

Traceback (most recent call last):
  File "c:\Users\user\Desktop\program\Reinforcement_learninng\finrl_achieve\project\New_Trading_Systeam.py", line 215, in main
    self.dataprovider.get_trade_data(self.targetsymbols, self.symbol_map,freq=self.engine_setting['FREQ_TIME'])
  File "c:\Users\user\Desktop\program\Reinforcement_learninng\finrl_achieve\project\Major\DataProvider.py", line 194, in get_trade_data
    finally_df = self.datatransformer.fix_data_different_len_and_na(finally_df)
  File "c:\Users\user\Desktop\program\Reinforcement_learninng\finrl_achieve\project\Major\Datatransformer.py", line 276, in fix_data_different_len_and_na
    all_times = set(df['date'])
  File "C:\Users\user\Desktop\program\Reinforcement_learninng\lib\site-packages\pandas\core\frame.py", line 4090, in __getitem__
    indexer = self.columns.get_loc(key)
  File "C:\Users\user\Desktop\program\Reinforcement_learninng\lib\site-packages\pandas\core\indexes\base.py", line 3809, in get_loc
    raise KeyError(key) from err
KeyError: 'date'

